<mujoco model="MuJoCo Model">
    <compiler angle="radian" meshdir="/Users/marcin2/code/gpr/cache/s3/stls/" texturedir="/Users/marcin2/code/gpr/cache/s3/textures/" />
    <option solver="CG" iterations="1000" />
    <size njmax="500" nconmax="100" />
    <default class="main">
        <default class="robot0:fetch">
            <joint armature="1" damping="50" />
            <geom type="mesh" solref="0.01 1" solimp="0.99 0.99 0.01" margin="0.001" material="robot0:geomMat" rgba="1 1 1 1" />
            <default class="robot0:fetchGripper">
                <joint type="slide" limited="true" solreflimit="0.01 1" solimplimit="0.99 0.999 0.01" armature="100" damping="1000" />
                <geom type="box" condim="4" />
            </default>
        </default>
    </default>
    <asset>
        <texture type="skybox" builtin="gradient" rgb1="1 1 1" rgb2="1 1 1" width="32" height="192" />
        <texture type="2d" name="texture_material1" file="wood.png" />
        <texture type="cube" name="robot0:texgeom" builtin="flat" rgb1="1 1 1" rgb2="1 1 1" width="32" height="192" />
        <texture type="cube" name="robot0:gripper_finger_tex" builtin="flat" rgb1="1 1 1" rgb2="1 1 1" width="32" height="192" />
        <texture type="cube" name="robot0:gripper_tex" builtin="flat" rgb1="1 1 1" rgb2="1 1 1" width="32" height="192" />
        <texture type="cube" name="robot0:arm_tex" builtin="flat" rgb1="1 1 1" rgb2="1 1 1" width="32" height="192" />
        <texture type="cube" name="robot0:head_tex" builtin="flat" rgb1="1 1 1" rgb2="1 1 1" width="32" height="192" />
        <texture type="cube" name="robot0:torso_tex" builtin="flat" rgb1="1 1 1" rgb2="1 1 1" width="32" height="192" />
        <texture type="cube" name="robot0:base_tex" builtin="flat" rgb1="1 1 1" rgb2="1 1 1" width="32" height="192" />
        <texture type="cube" name="texture_material0" file="chars/A.png" gridsize="3 4" gridlayout=".U..LFRB.D.." />
        <material name="material1" texture="texture_material1" />
        <material name="robot0:geomMat" texture="robot0:texgeom" specular="0.75" shininess="0.03" />
        <material name="robot0:gripper_finger_mat" texture="robot0:gripper_finger_tex" specular="0.75" shininess="0.03" />
        <material name="robot0:gripper_mat" texture="robot0:gripper_tex" specular="0.75" shininess="0.03" />
        <material name="robot0:arm_mat" texture="robot0:arm_tex" specular="0.75" shininess="0.03" />
        <material name="robot0:head_mat" texture="robot0:head_tex" specular="0.75" shininess="0.03" />
        <material name="robot0:torso_mat" texture="robot0:torso_tex" specular="0.75" shininess="0.03" />
        <material name="robot0:base_mat" texture="robot0:base_tex" specular="0.75" shininess="0.03" />
        <material name="material0" texture="texture_material0" />
        <mesh name="robot0:base_link" file="robot/fetch/base_link_collision.stl" />
        <mesh name="robot0:torso_lift_link" file="robot/fetch/torso_lift_link_collision.stl" />
        <mesh name="robot0:head_pan_link" file="robot/fetch/head_pan_link_collision.stl" />
        <mesh name="robot0:head_tilt_link" file="robot/fetch/head_tilt_link_collision.stl" />
        <mesh name="robot0:shoulder_pan_link" file="robot/fetch/shoulder_pan_link_collision.stl" />
        <mesh name="robot0:shoulder_lift_link" file="robot/fetch/shoulder_lift_link_collision.stl" />
        <mesh name="robot0:upperarm_roll_link" file="robot/fetch/upperarm_roll_link_collision.stl" />
        <mesh name="robot0:elbow_flex_link" file="robot/fetch/elbow_flex_link_collision.stl" />
        <mesh name="robot0:forearm_roll_link" file="robot/fetch/forearm_roll_link_collision.stl" />
        <mesh name="robot0:wrist_flex_link" file="robot/fetch/wrist_flex_link_collision.stl" />
        <mesh name="robot0:wrist_roll_link" file="robot/fetch/wrist_roll_link_collision.stl" />
        <mesh name="robot0:gripper_link" file="robot/fetch/gripper_link.stl" />
        <mesh name="robot0:estop_link" file="robot/fetch/estop_link.stl" />
        <mesh name="robot0:laser_link" file="robot/fetch/laser_link.stl" />
        <mesh name="robot0:torso_fixed_link" file="robot/fetch/torso_fixed_link.stl" />
    </asset>
    <worldbody>
        <geom name="floor0" size="0.75 0.7 1" pos="0.8 0.75 0" type="plane" material="material1" />
        <body name="floor0" pos="0.8 0.75 0">
            <inertial pos="0.8 0.75 0" mass="0" diaginertia="0 0 0" />
            <site name="target0" pos="0 0 0.5" size="0.02" rgba="1 0 0 1" />
        </body>
        <body name="robot0:mocap" pos="0 0 0" mocap="true">
            <inertial pos="0 0 0" quat="0.5 0.5 0.5 0.5" mass="0.441" diaginertia="0.133337 0.0800054 0.080005" />
            <geom size="0.005 0.005 0.005" type="box" contype="0" conaffinity="0" rgba="0 0.5 0 0.7" />
            <geom size="1 0.005 0.005" type="box" contype="0" conaffinity="0" rgba="0 0.5 0 0.1" />
            <geom size="0.005 1 0.001" type="box" contype="0" conaffinity="0" rgba="0 0.5 0 0.1" />
            <geom size="0.005 0.005 1" type="box" contype="0" conaffinity="0" rgba="0 0.5 0 0.1" />
        </body>
        <body name="robot0:base_link" childclass="robot0:fetch" pos="0.2869 0.2641 0">
            <inertial pos="-0.0036 0 0.0014" quat="0.760536 -0.0133006 -0.00610029 0.649131" mass="70.1294" diaginertia="1.2869 1.2236 0.9868" />
            <joint name="robot0:slide0" pos="0 0 0" axis="1 0 0" type="slide" armature="0.0001" damping="-2147483648" />
            <joint name="robot0:slide1" pos="0 0 0" axis="0 1 0" type="slide" armature="0.0001" damping="-2147483648" />
            <joint name="robot0:slide2" pos="0 0 0" axis="0 0 1" type="slide" armature="0.0001" damping="-2147483648" />
            <geom name="robot0:base_link" material="robot0:base_mat" mesh="robot0:base_link" />
            <body name="robot0:torso_lift_link" pos="-0.0869 0 0.3774">
                <inertial pos="-0.0013 -0.0009 0.2935" quat="0.999264 -0.000599978 0.0335988 0.0184993" mass="10.7796" diaginertia="0.3365 0.3354 0.0943" />
                <joint name="robot0:torso_lift_joint" pos="0 0 0" axis="0 0 1" type="slide" range="0.0386 0.3861" damping="10000000" />
                <geom name="robot0:torso_lift_link" material="robot0:torso_mat" mesh="robot0:torso_lift_link" />
                <body name="robot0:head_pan_link" pos="0.0531 0 0.603">
                    <inertial pos="0.0321 0.0161 0.039" quat="0.514806 0.545107 -0.453006 0.482306" mass="2.2556" diaginertia="0.0185 0.0128 0.0095" />
                    <joint name="robot0:head_pan_joint" pos="0 0 0" axis="0 0 1" range="-1.57 1.57" />
                    <geom name="robot0:head_pan_link" material="robot0:head_mat" mesh="robot0:head_pan_link" />
                    <body name="robot0:head_tilt_link" pos="0.1425 0 0.058">
                        <inertial pos="0.0081 0.0025 0.0113" quat="0.645787 0.659987 -0.273994 0.268895" mass="0.9087" diaginertia="0.0063 0.0059 0.0014" />
                        <joint name="robot0:head_tilt_joint" pos="0 0 0" axis="0 1 0" ref="0.06" range="-0.76 1.45" damping="1000" />
                        <geom name="robot0:head_tilt_link" material="robot0:head_mat" mesh="robot0:head_tilt_link" />
                        <body name="robot0:head_camera_link" pos="0.055 0 0.0225">
                            <inertial pos="0.055 0 0.0225" mass="0" diaginertia="0 0 0" />
                            <body name="robot0:head_camera_rgb_frame" pos="0 0.02 0">
                                <inertial pos="0 0.02 0" mass="0" diaginertia="0 0 0" />
                                <body name="robot0:head_camera_rgb_optical_frame" pos="0 0 0" quat="0.5 -0.5 0.5 -0.5">
                                    <inertial pos="0 0 0" quat="0.5 -0.5 0.5 -0.5" mass="0" diaginertia="0 0 0" />
                                    <camera name="head_camera_rgb" pos="0 0 0" quat="4.63268e-05 1 0 0" fovy="50" />
                                </body>
                            </body>
                            <body name="robot0:head_camera_depth_frame" pos="0 0.045 0">
                                <inertial pos="0 0.045 0" mass="0" diaginertia="0 0 0" />
                                <body name="robot0:head_camera_depth_optical_frame" pos="0 0 0" quat="0.5 -0.5 0.5 -0.5">
                                    <inertial pos="0 0 0" quat="0.5 -0.5 0.5 -0.5" mass="0" diaginertia="0 0 0" />
                                </body>
                            </body>
                        </body>
                    </body>
                </body>
                <body name="robot0:shoulder_pan_link" pos="0.1195 0 0.3486">
                    <inertial pos="0.0927 -0.0056 0.0564" quat="-0.136398 0.76239 -0.156198 0.612992" mass="2.5587" diaginertia="0.009 0.0086 0.0041" />
                    <joint name="robot0:shoulder_pan_joint" pos="0 0 0" axis="0 0 1" range="-1.6056 1.6056" />
                    <geom name="robot0:shoulder_pan_link" material="robot0:arm_mat" mesh="robot0:shoulder_pan_link" />
                    <body name="robot0:shoulder_lift_link" pos="0.117 0 0.06">
                        <inertial pos="0.1432 0.0072 -0.0001" quat="0.438181 0.438181 0.554975 0.554975" mass="2.6615" diaginertia="0.0116 0.0112 0.0023" />
                        <joint name="robot0:shoulder_lift_joint" pos="0 0 0" axis="0 1 0" range="-1.221 1.518" />
                        <geom name="robot0:shoulder_lift_link" material="robot0:arm_mat" mesh="robot0:shoulder_lift_link" />
                        <body name="robot0:upperarm_roll_link" pos="0.219 0 0">
                            <inertial pos="0.1165 0.0014 0" quat="-0.0135995 0.706976 0.0135995 0.706976" mass="2.3311" diaginertia="0.0047 0.0045 0.0019" />
                            <joint name="robot0:upperarm_roll_joint" pos="0 0 0" axis="1 0 0" />
                            <geom name="robot0:upperarm_roll_link" material="robot0:arm_mat" mesh="robot0:upperarm_roll_link" />
                            <body name="robot0:elbow_flex_link" pos="0.133 0 0">
                                <inertial pos="0.1279 0.0073 0" quat="0.433186 0.433186 0.558882 0.558882" mass="2.1299" diaginertia="0.0086 0.0084 0.002" />
                                <joint name="robot0:elbow_flex_joint" pos="0 0 0" axis="0 1 0" range="-2.251 2.251" />
                                <geom name="robot0:elbow_flex_link" material="robot0:arm_mat" mesh="robot0:elbow_flex_link" />
                                <body name="robot0:forearm_roll_link" pos="0.197 0 0">
                                    <inertial pos="0.1097 -0.0266 0" quat="-0.0714982 0.703483 0.0714982 0.703483" mass="1.6563" diaginertia="0.0035 0.0031 0.0015" />
                                    <joint name="robot0:forearm_roll_joint" pos="0 0 0" axis="1 0 0" stiffness="10" armature="2.7538" damping="3.5247" />
                                    <geom name="robot0:forearm_roll_link" material="robot0:arm_mat" mesh="robot0:forearm_roll_link" />
                                    <body name="robot0:wrist_flex_link" pos="0.1245 0 0">
                                        <inertial pos="0.0882 0.0009 -0.0001" quat="0.489492 0.489492 0.510292 0.510292" mass="1.725" diaginertia="0.0042 0.0042 0.0018" />
                                        <joint name="robot0:wrist_flex_joint" pos="0 0 0" axis="0 1 0" range="-2.16 2.16" />
                                        <geom name="robot0:wrist_flex_link" material="robot0:arm_mat" mesh="robot0:wrist_flex_link" />
                                        <body name="robot0:wrist_roll_link" pos="0.1385 0 0">
                                            <inertial pos="0.0095 0.0004 -0.0002" mass="0.1354" diaginertia="0.0001 0.0001 0.0001" />
                                            <joint name="robot0:wrist_roll_joint" pos="0 0 0" axis="1 0 0" />
                                            <geom name="robot0:wrist_roll_link" material="robot0:arm_mat" mesh="robot0:wrist_roll_link" />
                                            <body name="robot0:gripper_link" pos="0.1664 0 0">
                                                <inertial pos="-0.09 -0.0001 -0.0017" quat="0 0.707107 0 0.707107" mass="1.5175" diaginertia="0.0024 0.0019 0.0013" />
                                                <geom name="robot0:gripper_link" material="robot0:gripper_mat" mesh="robot0:gripper_link" />
                                                <site name="robot0:grip" pos="0.02 0 0" size="0.02" rgba="0 0 0 0" />
                                                <body name="robot0:gipper_camera_link" pos="0.055 0 0.0225">
                                                    <inertial pos="0.055 0 0.0225" mass="0" diaginertia="0 0 0" />
                                                    <body name="robot0:gripper_camera_rgb_frame" pos="0 0.02 0">
                                                        <inertial pos="0 0.02 0" mass="0" diaginertia="0 0 0" />
                                                        <body name="robot0:gripper_camera_rgb_optical_frame" pos="0 0 0" quat="0.5 -0.5 0.5 -0.5">
                                                            <inertial pos="0 0 0" quat="0.5 -0.5 0.5 -0.5" mass="0" diaginertia="0 0 0" />
                                                            <camera name="gripper_camera_rgb" pos="0 0 0" quat="4.63268e-05 1 0 0" fovy="50" />
                                                        </body>
                                                    </body>
                                                    <body name="robot0:gripper_camera_depth_frame" pos="0 0.045 0">
                                                        <inertial pos="0 0.045 0" mass="0" diaginertia="0 0 0" />
                                                        <body name="robot0:gripper_camera_depth_optical_frame" pos="0 0 0" quat="0.5 -0.5 0.5 -0.5">
                                                            <inertial pos="0 0 0" quat="0.5 -0.5 0.5 -0.5" mass="0" diaginertia="0 0 0" />
                                                        </body>
                                                    </body>
                                                </body>
                                                <body name="robot0:r_gripper_finger_link" childclass="robot0:fetchGripper" pos="0 0.0159 0">
                                                    <inertial pos="-0.01 0 0" mass="4" diaginertia="0.1 0.1 0.1" />
                                                    <joint name="robot0:r_gripper_finger_joint" pos="0 0 0" axis="0 1 0" range="0 0.05" />
                                                    <geom name="robot0:r_gripper_finger_link" size="0.0385 0.007 0.0135" pos="0 -0.008 0" friction="1 0.05 0.01" material="robot0:gripper_finger_mat" />
                                                </body>
                                                <body name="robot0:l_gripper_finger_link" childclass="robot0:fetchGripper" pos="0 -0.0159 0">
                                                    <inertial pos="-0.01 0 0" mass="4" diaginertia="0.1 0.1 0.1" />
                                                    <joint name="robot0:l_gripper_finger_joint" pos="0 0 0" axis="0 -1 0" range="0 0.05" />
                                                    <geom name="robot0:l_gripper_finger_link" size="0.0385 0.007 0.0135" pos="0 0.008 0" friction="1 0.05 0.01" material="robot0:gripper_finger_mat" />
                                                </body>
                                            </body>
                                        </body>
                                    </body>
                                </body>
                            </body>
                        </body>
                    </body>
                </body>
            </body>
            <body name="robot0:estop_link" pos="-0.1246 0.2389 0.3113" quat="0.707107 0.707107 0 0">
                <inertial pos="0.0024 -0.0033 0.0067" quat="0.37738 -0.18139 0.137493 0.897651" mass="0.002" diaginertia="0 0 0" />
                <geom name="robot0:estop_link" rgba="0.8 0 0 1" mesh="robot0:estop_link" />
            </body>
            <body name="robot0:laser_link" pos="0.235 0 0.2878" quat="0 1 0 0">
                <inertial pos="-0.0306 0.0007 0.0552" quat="0.587815 0.537814 -0.457812 0.39451" mass="0.0083" diaginertia="0 0 0" />
                <geom name="robot0:laser_link" rgba="0.7922 0.8196 0.9333 1" mesh="robot0:laser_link" />
                <camera name="lidar" pos="0 0 0.02" quat="0.490009 -0.499494 -0.50029 0.510007" fovy="25" />
            </body>
            <body name="robot0:torso_fixed_link" pos="-0.0869 0 0.3774">
                <inertial pos="-0.0722 0.0057 0.2656" quat="0.999473 0.0248993 0.0176995 0.0109997" mass="13.2775" diaginertia="0.3865 0.3394 0.1009" />
                <geom name="robot0:torso_fixed_link" mesh="robot0:torso_fixed_link" />
            </body>
            <body name="robot0:external_camera_body_0" pos="0 0 0">
                <inertial pos="0 0 0" mass="0" diaginertia="0 0 0" />
                <camera name="external_camera_0" pos="1.3 0 1.2" quat="0.65823 0.258891 0.259097 0.657706" fovy="43.3" />
            </body>
        </body>
        <body name="table_table20:table_table20" pos="0.25 0.35 0.2">
            <inertial pos="0 0 0" mass="2000" diaginertia="108.333 68.3333 123.333" />
            <joint name="table_table20:slide0" pos="0 0 0" axis="1 0 0" type="slide" damping="10000" />
            <joint name="table_table20:slide1" pos="0 0 0" axis="0 1 0" type="slide" damping="10000" />
            <joint name="table_table20:slide2" pos="0 0 0" axis="0 0 1" type="slide" damping="10000" />
            <geom size="0.25 0.35 0.2" type="box" rgba="1.5 1.5 1.5 1" />
        </body>
        <body name="geom0" pos="0.025 0.025 0.025">
            <inertial pos="0 0 0" mass="2" diaginertia="0.000833333 0.000833333 0.000833333" />
            <joint name="geom0:slide0" pos="0 0 0" axis="1 0 0" type="slide" damping="0.01" />
            <joint name="geom0:slide1" pos="0 0 0" axis="0 1 0" type="slide" damping="0.01" />
            <joint name="geom0:slide2" pos="0 0 0" axis="0 0 1" type="slide" damping="0.01" />
            <joint name="geom0:hinge0" pos="0 0 0" axis="1 0 0" damping="0.01" />
            <joint name="geom0:hinge1" pos="0 0 0" axis="0 1 0" damping="0.01" />
            <joint name="geom0:hinge2" pos="0 0 0" axis="0 0 1" damping="0.01" />
            <geom name="geom0" size="0.025 0.025 0.025" type="box" material="material0" />
            <site name="geom0" pos="0 0 0" size="0.02" rgba="1 0 0 1" />
        </body>
    </worldbody>
    <contact>
        <exclude body1="robot0:torso_lift_link" body2="robot0:shoulder_pan_link" />
        <exclude body1="robot0:torso_lift_link" body2="robot0:torso_fixed_link" />
        <exclude body1="robot0:r_gripper_finger_link" body2="robot0:l_gripper_finger_link" />
    </contact>
    <equality>
        <weld body1="robot0:mocap" body2="robot0:gripper_link" />
    </equality>
    <actuator>
        <general name="robot0:l_gripper_finger_joint" joint="robot0:l_gripper_finger_joint" ctrllimited="true" ctrlrange="0 0.2" biastype="affine" gainprm="30000 0 0" biasprm="0 -30000 0" />
        <general name="robot0:r_gripper_finger_joint" joint="robot0:r_gripper_finger_joint" ctrllimited="true" ctrlrange="0 0.2" biastype="affine" gainprm="30000 0 0" biasprm="0 -30000 0" />
    </actuator>
</mujoco>
